[2024-11-21T05:48:15.394+0000] {local_task_job_runner.py:123} INFO - ::group::Pre task execution logs
[2024-11-21T05:48:15.500+0000] {taskinstance.py:2613} INFO - Dependencies all met for dep_context=non-requeueable deps ti=<TaskInstance: dados_metereologicos.extract scheduled__2024-11-19T00:00:00+00:00 [queued]>
[2024-11-21T05:48:15.568+0000] {taskinstance.py:2613} INFO - Dependencies all met for dep_context=requeueable deps ti=<TaskInstance: dados_metereologicos.extract scheduled__2024-11-19T00:00:00+00:00 [queued]>
[2024-11-21T05:48:15.571+0000] {taskinstance.py:2866} INFO - Starting attempt 1 of 1
[2024-11-21T05:48:15.648+0000] {taskinstance.py:2889} INFO - Executing <Task(PythonOperator): extract> on 2024-11-19 00:00:00+00:00
[2024-11-21T05:48:15.677+0000] {warnings.py:112} WARNING - /home/***/.local/lib/python3.12/site-packages/***/task/task_runner/standard_task_runner.py:70: DeprecationWarning: This process (pid=235) is multi-threaded, use of fork() may lead to deadlocks in the child.
  pid = os.fork()

[2024-11-21T05:48:15.689+0000] {standard_task_runner.py:72} INFO - Started process 262 to run task
[2024-11-21T05:48:15.699+0000] {standard_task_runner.py:104} INFO - Running: ['***', 'tasks', 'run', 'dados_metereologicos', 'extract', 'scheduled__2024-11-19T00:00:00+00:00', '--job-id', '53', '--raw', '--subdir', 'DAGS_FOLDER/dados_metereologicos.py', '--cfg-path', '/tmp/tmpk7qi28iu']
[2024-11-21T05:48:15.706+0000] {standard_task_runner.py:105} INFO - Job 53: Subtask extract
[2024-11-21T05:48:17.048+0000] {task_command.py:467} INFO - Running <TaskInstance: dados_metereologicos.extract scheduled__2024-11-19T00:00:00+00:00 [running]> on host bf751b86ec1d
[2024-11-21T05:48:17.465+0000] {taskinstance.py:3132} INFO - Exporting env vars: AIRFLOW_CTX_DAG_OWNER='***' AIRFLOW_CTX_DAG_ID='dados_metereologicos' AIRFLOW_CTX_TASK_ID='extract' AIRFLOW_CTX_EXECUTION_DATE='2024-11-19T00:00:00+00:00' AIRFLOW_CTX_TRY_NUMBER='1' AIRFLOW_CTX_DAG_RUN_ID='scheduled__2024-11-19T00:00:00+00:00'
[2024-11-21T05:48:17.469+0000] {logging_mixin.py:190} INFO - Task instance is in running state
[2024-11-21T05:48:17.475+0000] {logging_mixin.py:190} INFO -  Previous state of the Task instance: queued
[2024-11-21T05:48:17.477+0000] {logging_mixin.py:190} INFO - Current task name:extract state:running start_date:2024-11-21 05:48:15.502472+00:00
[2024-11-21T05:48:17.480+0000] {logging_mixin.py:190} INFO - Dag name:dados_metereologicos and current dag run status:running
[2024-11-21T05:48:17.482+0000] {taskinstance.py:731} INFO - ::endgroup::
[2024-11-21T05:48:17.858+0000] {taskinstance.py:3311} ERROR - Task failed with exception
Traceback (most recent call last):
  File "/home/airflow/.local/lib/python3.12/site-packages/airflow/models/taskinstance.py", line 767, in _execute_task
    result = _execute_callable(context=context, **execute_callable_kwargs)
             ^^^^^^^^^^^^^^^^^^^^^^^^^^^^^^^^^^^^^^^^^^^^^^^^^^^^^^^^^^^^^
  File "/home/airflow/.local/lib/python3.12/site-packages/airflow/models/taskinstance.py", line 733, in _execute_callable
    return ExecutionCallableRunner(
           ^^^^^^^^^^^^^^^^^^^^^^^^
  File "/home/airflow/.local/lib/python3.12/site-packages/airflow/utils/operator_helpers.py", line 252, in run
    return self.func(*args, **kwargs)
           ^^^^^^^^^^^^^^^^^^^^^^^^^^
  File "/home/airflow/.local/lib/python3.12/site-packages/airflow/models/baseoperator.py", line 417, in wrapper
    return func(self, *args, **kwargs)
           ^^^^^^^^^^^^^^^^^^^^^^^^^^^
  File "/home/airflow/.local/lib/python3.12/site-packages/airflow/operators/python.py", line 238, in execute
    return_value = self.execute_callable()
                   ^^^^^^^^^^^^^^^^^^^^^^^
  File "/home/airflow/.local/lib/python3.12/site-packages/airflow/operators/python.py", line 256, in execute_callable
    return runner.run(*self.op_args, **self.op_kwargs)
           ^^^^^^^^^^^^^^^^^^^^^^^^^^^^^^^^^^^^^^^^^^^
  File "/home/airflow/.local/lib/python3.12/site-packages/airflow/utils/operator_helpers.py", line 252, in run
    return self.func(*args, **kwargs)
           ^^^^^^^^^^^^^^^^^^^^^^^^^^
  File "/opt/airflow/dags/dados_metereologicos.py", line 23, in extract
    raise Exception("Falha na extração de dados")
Exception: Falha na extração de dados
[2024-11-21T05:48:17.898+0000] {logging_mixin.py:190} INFO - Task instance in failure state
[2024-11-21T05:48:17.900+0000] {logging_mixin.py:190} INFO - Task start:2024-11-21 05:48:15.502472+00:00 end:2024-11-21 05:48:17.897462+00:00 duration:2.39499
[2024-11-21T05:48:17.902+0000] {logging_mixin.py:190} INFO - Task:<Task(PythonOperator): extract> dag:<DAG: dados_metereologicos> dagrun:<DagRun dados_metereologicos @ 2024-11-19 00:00:00+00:00: scheduled__2024-11-19T00:00:00+00:00, state:running, queued_at: 2024-11-21 05:48:04.411803+00:00. externally triggered: False>
[2024-11-21T05:48:17.904+0000] {logging_mixin.py:190} INFO - Failure caused by Falha na extração de dados
[2024-11-21T05:48:17.907+0000] {taskinstance.py:1225} INFO - Marking task as FAILED. dag_id=dados_metereologicos, task_id=extract, run_id=scheduled__2024-11-19T00:00:00+00:00, execution_date=20241119T000000, start_date=20241121T054815, end_date=20241121T054817
[2024-11-21T05:48:17.952+0000] {taskinstance.py:340} INFO - ::group::Post task execution logs
[2024-11-21T05:48:17.958+0000] {standard_task_runner.py:124} ERROR - Failed to execute job 53 for task extract (Falha na extração de dados; 262)
Traceback (most recent call last):
  File "/home/airflow/.local/lib/python3.12/site-packages/airflow/task/task_runner/standard_task_runner.py", line 117, in _start_by_fork
    ret = args.func(args, dag=self.dag)
          ^^^^^^^^^^^^^^^^^^^^^^^^^^^^^
  File "/home/airflow/.local/lib/python3.12/site-packages/airflow/cli/cli_config.py", line 49, in command
    return func(*args, **kwargs)
           ^^^^^^^^^^^^^^^^^^^^^
  File "/home/airflow/.local/lib/python3.12/site-packages/airflow/utils/cli.py", line 116, in wrapper
    return f(*args, **kwargs)
           ^^^^^^^^^^^^^^^^^^
  File "/home/airflow/.local/lib/python3.12/site-packages/airflow/cli/commands/task_command.py", line 483, in task_run
    task_return_code = _run_task_by_selected_method(args, _dag, ti)
                       ^^^^^^^^^^^^^^^^^^^^^^^^^^^^^^^^^^^^^^^^^^^^
  File "/home/airflow/.local/lib/python3.12/site-packages/airflow/cli/commands/task_command.py", line 256, in _run_task_by_selected_method
    return _run_raw_task(args, ti)
           ^^^^^^^^^^^^^^^^^^^^^^^
  File "/home/airflow/.local/lib/python3.12/site-packages/airflow/cli/commands/task_command.py", line 341, in _run_raw_task
    return ti._run_raw_task(
           ^^^^^^^^^^^^^^^^^
  File "/home/airflow/.local/lib/python3.12/site-packages/airflow/utils/session.py", line 97, in wrapper
    return func(*args, session=session, **kwargs)
           ^^^^^^^^^^^^^^^^^^^^^^^^^^^^^^^^^^^^^^
  File "/home/airflow/.local/lib/python3.12/site-packages/airflow/models/taskinstance.py", line 3005, in _run_raw_task
    return _run_raw_task(
           ^^^^^^^^^^^^^^
  File "/home/airflow/.local/lib/python3.12/site-packages/airflow/models/taskinstance.py", line 273, in _run_raw_task
    TaskInstance._execute_task_with_callbacks(
  File "/home/airflow/.local/lib/python3.12/site-packages/airflow/models/taskinstance.py", line 3159, in _execute_task_with_callbacks
    result = self._execute_task(context, task_orig)
             ^^^^^^^^^^^^^^^^^^^^^^^^^^^^^^^^^^^^^^
  File "/home/airflow/.local/lib/python3.12/site-packages/airflow/models/taskinstance.py", line 3183, in _execute_task
    return _execute_task(self, context, task_orig)
           ^^^^^^^^^^^^^^^^^^^^^^^^^^^^^^^^^^^^^^^
  File "/home/airflow/.local/lib/python3.12/site-packages/airflow/models/taskinstance.py", line 767, in _execute_task
    result = _execute_callable(context=context, **execute_callable_kwargs)
             ^^^^^^^^^^^^^^^^^^^^^^^^^^^^^^^^^^^^^^^^^^^^^^^^^^^^^^^^^^^^^
  File "/home/airflow/.local/lib/python3.12/site-packages/airflow/models/taskinstance.py", line 733, in _execute_callable
    return ExecutionCallableRunner(
           ^^^^^^^^^^^^^^^^^^^^^^^^
  File "/home/airflow/.local/lib/python3.12/site-packages/airflow/utils/operator_helpers.py", line 252, in run
    return self.func(*args, **kwargs)
           ^^^^^^^^^^^^^^^^^^^^^^^^^^
  File "/home/airflow/.local/lib/python3.12/site-packages/airflow/models/baseoperator.py", line 417, in wrapper
    return func(self, *args, **kwargs)
           ^^^^^^^^^^^^^^^^^^^^^^^^^^^
  File "/home/airflow/.local/lib/python3.12/site-packages/airflow/operators/python.py", line 238, in execute
    return_value = self.execute_callable()
                   ^^^^^^^^^^^^^^^^^^^^^^^
  File "/home/airflow/.local/lib/python3.12/site-packages/airflow/operators/python.py", line 256, in execute_callable
    return runner.run(*self.op_args, **self.op_kwargs)
           ^^^^^^^^^^^^^^^^^^^^^^^^^^^^^^^^^^^^^^^^^^^
  File "/home/airflow/.local/lib/python3.12/site-packages/airflow/utils/operator_helpers.py", line 252, in run
    return self.func(*args, **kwargs)
           ^^^^^^^^^^^^^^^^^^^^^^^^^^
  File "/opt/airflow/dags/dados_metereologicos.py", line 23, in extract
    raise Exception("Falha na extração de dados")
Exception: Falha na extração de dados
[2024-11-21T05:48:18.025+0000] {local_task_job_runner.py:266} INFO - Task exited with return code 1
[2024-11-21T05:48:18.471+0000] {taskinstance.py:3895} INFO - 0 downstream tasks scheduled from follow-on schedule check
[2024-11-21T05:48:18.484+0000] {local_task_job_runner.py:245} INFO - ::endgroup::
