[2024-11-21T06:03:09.816+0000] {local_task_job_runner.py:123} INFO - ::group::Pre task execution logs
[2024-11-21T06:03:09.853+0000] {taskinstance.py:2613} INFO - Dependencies all met for dep_context=non-requeueable deps ti=<TaskInstance: countries_pipeline.print manual__2024-11-21T06:02:41.915879+00:00 [queued]>
[2024-11-21T06:03:09.873+0000] {taskinstance.py:2613} INFO - Dependencies all met for dep_context=requeueable deps ti=<TaskInstance: countries_pipeline.print manual__2024-11-21T06:02:41.915879+00:00 [queued]>
[2024-11-21T06:03:09.876+0000] {taskinstance.py:2866} INFO - Starting attempt 1 of 1
[2024-11-21T06:03:09.909+0000] {taskinstance.py:2889} INFO - Executing <Task(BashOperator): print> on 2024-11-21 06:02:41.915879+00:00
[2024-11-21T06:03:09.924+0000] {warnings.py:112} WARNING - /home/***/.local/lib/python3.12/site-packages/***/task/task_runner/standard_task_runner.py:70: DeprecationWarning: This process (pid=204) is multi-threaded, use of fork() may lead to deadlocks in the child.
  pid = os.fork()

[2024-11-21T06:03:09.927+0000] {standard_task_runner.py:72} INFO - Started process 208 to run task
[2024-11-21T06:03:09.930+0000] {standard_task_runner.py:104} INFO - Running: ['***', 'tasks', 'run', 'countries_pipeline', 'print', 'manual__2024-11-21T06:02:41.915879+00:00', '--job-id', '65', '--raw', '--subdir', 'DAGS_FOLDER/paises_api.py', '--cfg-path', '/tmp/tmpgi05mj3l']
[2024-11-21T06:03:09.932+0000] {standard_task_runner.py:105} INFO - Job 65: Subtask print
[2024-11-21T06:03:10.515+0000] {task_command.py:467} INFO - Running <TaskInstance: countries_pipeline.print manual__2024-11-21T06:02:41.915879+00:00 [running]> on host bf751b86ec1d
[2024-11-21T06:03:10.850+0000] {taskinstance.py:3132} INFO - Exporting env vars: AIRFLOW_CTX_DAG_OWNER='***' AIRFLOW_CTX_DAG_ID='countries_pipeline' AIRFLOW_CTX_TASK_ID='print' AIRFLOW_CTX_EXECUTION_DATE='2024-11-21T06:02:41.915879+00:00' AIRFLOW_CTX_TRY_NUMBER='1' AIRFLOW_CTX_DAG_RUN_ID='manual__2024-11-21T06:02:41.915879+00:00'
[2024-11-21T06:03:10.853+0000] {logging_mixin.py:190} INFO - Task instance is in running state
[2024-11-21T06:03:10.854+0000] {logging_mixin.py:190} INFO -  Previous state of the Task instance: queued
[2024-11-21T06:03:10.856+0000] {logging_mixin.py:190} INFO - Current task name:print state:running start_date:2024-11-21 06:03:09.854680+00:00
[2024-11-21T06:03:10.857+0000] {logging_mixin.py:190} INFO - Dag name:countries_pipeline and current dag run status:running
[2024-11-21T06:03:10.860+0000] {taskinstance.py:731} INFO - ::endgroup::
[2024-11-21T06:03:10.862+0000] {subprocess.py:78} INFO - Tmp dir root location: /tmp
[2024-11-21T06:03:10.865+0000] {subprocess.py:88} INFO - Running command: ['/usr/bin/bash', '-c', 'echo [{"nome_comum":"Italy","population":59554023,"area":301336.0,"region":"Europe","densidade_populacional":197.6332831125},{"nome_comum":"Indonesia","population":273523621,"area":1904569.0,"region":"Asia","densidade_populacional":143.614445578},{"nome_comum":"South Africa","population":59308690,"area":1221037.0,"region":"Africa","densidade_populacional":48.5723937931},{"nome_comum":"France","population":67391582,"area":551695.0,"region":"Europe","densidade_populacional":122.1536936169},{"nome_comum":"Mexico","population":128932753,"area":1964375.0,"region":"Americas","densidade_populacional":65.6355090041},{"nome_comum":"China","population":1402112000,"area":9706961.0,"region":"Asia","densidade_populacional":144.4439717024},{"nome_comum":"Egypt","population":102334403,"area":1002450.0,"region":"Africa","densidade_populacional":102.0842964736},{"nome_comum":"Bangladesh","population":164689383,"area":147570.0,"region":"Asia","densidade_populacional":1116.0085586501},{"nome_comum":"Turkey","population":84339067,"area":783562.0,"region":"Asia","densidade_populacional":107.6354736447},{"nome_comum":"United Kingdom","population":67215293,"area":242900.0,"region":"Europe","densidade_populacional":276.7200205846},{"nome_comum":"Colombia","population":50882884,"area":1141748.0,"region":"Americas","densidade_populacional":44.5657745842},{"nome_comum":"Pakistan","population":220892331,"area":881912.0,"region":"Asia","densidade_populacional":250.469809913},{"nome_comum":"India","population":1380004385,"area":3287590.0,"region":"Asia","densidade_populacional":419.761705383},{"nome_comum":"Germany","population":83240525,"area":357114.0,"region":"Europe","densidade_populacional":233.0923038582},{"nome_comum":"Russia","population":144104080,"area":17098242.0,"region":"Europe","densidade_populacional":8.4280056394},{"nome_comum":"Ethiopia","population":114963583,"area":1104300.0,"region":"Africa","densidade_populacional":104.1053907453},{"nome_comum":"Thailand","population":69799978,"area":513120.0,"region":"Asia","densidade_populacional":136.0305152791},{"nome_comum":"Philippines","population":109581085,"area":342353.0,"region":"Asia","densidade_populacional":320.0821520477},{"nome_comum":"DR Congo","population":108407721,"area":2344858.0,"region":"Africa","densidade_populacional":46.2321048865},{"nome_comum":"Kenya","population":53771300,"area":580367.0,"region":"Africa","densidade_populacional":92.6505125205},{"nome_comum":"Vietnam","population":97338583,"area":331212.0,"region":"Asia","densidade_populacional":293.886039757},{"nome_comum":"Tanzania","population":59734213,"area":945087.0,"region":"Africa","densidade_populacional":63.2049885354},{"nome_comum":"South Korea","population":51780579,"area":100210.0,"region":"Asia","densidade_populacional":516.7206765792},{"nome_comum":"Japan","population":125836021,"area":377930.0,"region":"Asia","densidade_populacional":332.9611859339},{"nome_comum":"United States","population":329484123,"area":9372610.0,"region":"Americas","densidade_populacional":35.1539350298},{"nome_comum":"Nigeria","population":206139587,"area":923768.0,"region":"Africa","densidade_populacional":223.1508203358},{"nome_comum":"Iran","population":83992953,"area":1648195.0,"region":"Asia","densidade_populacional":50.9605677726},{"nome_comum":"Brazil","population":212559409,"area":8515767.0,"region":"Americas","densidade_populacional":24.9606886849},{"nome_comum":"Myanmar","population":54409794,"area":676578.0,"region":"Asia","densidade_populacional":80.4191002368}]']
[2024-11-21T06:03:10.901+0000] {subprocess.py:99} INFO - Output:
[2024-11-21T06:03:45.507+0000] {job.py:239} ERROR - Job heartbeat failed with error
Traceback (most recent call last):
  File "/home/airflow/.local/lib/python3.12/site-packages/sqlalchemy/engine/base.py", line 3371, in _wrap_pool_connect
    return fn()
           ^^^^
  File "/home/airflow/.local/lib/python3.12/site-packages/sqlalchemy/pool/base.py", line 327, in connect
    return _ConnectionFairy._checkout(self)
           ^^^^^^^^^^^^^^^^^^^^^^^^^^^^^^^^
  File "/home/airflow/.local/lib/python3.12/site-packages/sqlalchemy/pool/base.py", line 894, in _checkout
    fairy = _ConnectionRecord.checkout(pool)
            ^^^^^^^^^^^^^^^^^^^^^^^^^^^^^^^^
  File "/home/airflow/.local/lib/python3.12/site-packages/sqlalchemy/pool/base.py", line 493, in checkout
    rec = pool._do_get()
          ^^^^^^^^^^^^^^
  File "/home/airflow/.local/lib/python3.12/site-packages/sqlalchemy/pool/impl.py", line 256, in _do_get
    return self._create_connection()
           ^^^^^^^^^^^^^^^^^^^^^^^^^
  File "/home/airflow/.local/lib/python3.12/site-packages/sqlalchemy/pool/base.py", line 273, in _create_connection
    return _ConnectionRecord(self)
           ^^^^^^^^^^^^^^^^^^^^^^^
  File "/home/airflow/.local/lib/python3.12/site-packages/sqlalchemy/pool/base.py", line 388, in __init__
    self.__connect()
  File "/home/airflow/.local/lib/python3.12/site-packages/sqlalchemy/pool/base.py", line 690, in __connect
    with util.safe_reraise():
         ^^^^^^^^^^^^^^^^^^^
  File "/home/airflow/.local/lib/python3.12/site-packages/sqlalchemy/util/langhelpers.py", line 70, in __exit__
    compat.raise_(
  File "/home/airflow/.local/lib/python3.12/site-packages/sqlalchemy/util/compat.py", line 211, in raise_
    raise exception
  File "/home/airflow/.local/lib/python3.12/site-packages/sqlalchemy/pool/base.py", line 686, in __connect
    self.dbapi_connection = connection = pool._invoke_creator(self)
                                         ^^^^^^^^^^^^^^^^^^^^^^^^^^
  File "/home/airflow/.local/lib/python3.12/site-packages/sqlalchemy/engine/create.py", line 574, in connect
    return dialect.connect(*cargs, **cparams)
           ^^^^^^^^^^^^^^^^^^^^^^^^^^^^^^^^^^
  File "/home/airflow/.local/lib/python3.12/site-packages/sqlalchemy/engine/default.py", line 598, in connect
    return self.dbapi.connect(*cargs, **cparams)
           ^^^^^^^^^^^^^^^^^^^^^^^^^^^^^^^^^^^^^
  File "/home/airflow/.local/lib/python3.12/site-packages/psycopg2/__init__.py", line 122, in connect
    conn = _connect(dsn, connection_factory=connection_factory, **kwasync)
           ^^^^^^^^^^^^^^^^^^^^^^^^^^^^^^^^^^^^^^^^^^^^^^^^^^^^^^^^^^^^^^^
psycopg2.OperationalError: could not translate host name "postgres" to address: Temporary failure in name resolution


The above exception was the direct cause of the following exception:

Traceback (most recent call last):
  File "/home/airflow/.local/lib/python3.12/site-packages/airflow/jobs/job.py", line 233, in heartbeat
    heartbeat_callback(session)
  File "/home/airflow/.local/lib/python3.12/site-packages/airflow/utils/session.py", line 94, in wrapper
    return func(*args, **kwargs)
           ^^^^^^^^^^^^^^^^^^^^^
  File "/home/airflow/.local/lib/python3.12/site-packages/airflow/jobs/local_task_job_runner.py", line 284, in heartbeat_callback
    self.task_instance.refresh_from_db()
  File "/home/airflow/.local/lib/python3.12/site-packages/airflow/utils/session.py", line 97, in wrapper
    return func(*args, session=session, **kwargs)
           ^^^^^^^^^^^^^^^^^^^^^^^^^^^^^^^^^^^^^^
  File "/home/airflow/.local/lib/python3.12/site-packages/airflow/models/taskinstance.py", line 2359, in refresh_from_db
    _refresh_from_db(task_instance=self, session=session, lock_for_update=lock_for_update)
  File "/home/airflow/.local/lib/python3.12/site-packages/airflow/models/taskinstance.py", line 872, in _refresh_from_db
    ti = TaskInstance.get_task_instance(
         ^^^^^^^^^^^^^^^^^^^^^^^^^^^^^^^
  File "/home/airflow/.local/lib/python3.12/site-packages/airflow/api_internal/internal_api_call.py", line 166, in wrapper
    return func(*args, **kwargs)
           ^^^^^^^^^^^^^^^^^^^^^
  File "/home/airflow/.local/lib/python3.12/site-packages/airflow/utils/session.py", line 94, in wrapper
    return func(*args, **kwargs)
           ^^^^^^^^^^^^^^^^^^^^^
  File "/home/airflow/.local/lib/python3.12/site-packages/airflow/models/taskinstance.py", line 2345, in get_task_instance
    return query.one_or_none()
           ^^^^^^^^^^^^^^^^^^^
  File "/home/airflow/.local/lib/python3.12/site-packages/sqlalchemy/orm/query.py", line 2850, in one_or_none
    return self._iter().one_or_none()
           ^^^^^^^^^^^^
  File "/home/airflow/.local/lib/python3.12/site-packages/sqlalchemy/orm/query.py", line 2916, in _iter
    result = self.session.execute(
             ^^^^^^^^^^^^^^^^^^^^^
  File "/home/airflow/.local/lib/python3.12/site-packages/sqlalchemy/orm/session.py", line 1716, in execute
    conn = self._connection_for_bind(bind)
           ^^^^^^^^^^^^^^^^^^^^^^^^^^^^^^^
  File "/home/airflow/.local/lib/python3.12/site-packages/sqlalchemy/orm/session.py", line 1555, in _connection_for_bind
    return self._transaction._connection_for_bind(
           ^^^^^^^^^^^^^^^^^^^^^^^^^^^^^^^^^^^^^^^
  File "/home/airflow/.local/lib/python3.12/site-packages/sqlalchemy/orm/session.py", line 750, in _connection_for_bind
    conn = bind.connect()
           ^^^^^^^^^^^^^^
  File "/home/airflow/.local/lib/python3.12/site-packages/sqlalchemy/future/engine.py", line 412, in connect
    return super(Engine, self).connect()
           ^^^^^^^^^^^^^^^^^^^^^^^^^^^^^
  File "/home/airflow/.local/lib/python3.12/site-packages/sqlalchemy/engine/base.py", line 3325, in connect
    return self._connection_cls(self, close_with_result=close_with_result)
           ^^^^^^^^^^^^^^^^^^^^^^^^^^^^^^^^^^^^^^^^^^^^^^^^^^^^^^^^^^^^^^^
  File "/home/airflow/.local/lib/python3.12/site-packages/sqlalchemy/engine/base.py", line 96, in __init__
    else engine.raw_connection()
         ^^^^^^^^^^^^^^^^^^^^^^^
  File "/home/airflow/.local/lib/python3.12/site-packages/sqlalchemy/engine/base.py", line 3404, in raw_connection
    return self._wrap_pool_connect(self.pool.connect, _connection)
           ^^^^^^^^^^^^^^^^^^^^^^^^^^^^^^^^^^^^^^^^^^^^^^^^^^^^^^^
  File "/home/airflow/.local/lib/python3.12/site-packages/sqlalchemy/engine/base.py", line 3374, in _wrap_pool_connect
    Connection._handle_dbapi_exception_noconnection(
  File "/home/airflow/.local/lib/python3.12/site-packages/sqlalchemy/engine/base.py", line 2208, in _handle_dbapi_exception_noconnection
    util.raise_(
  File "/home/airflow/.local/lib/python3.12/site-packages/sqlalchemy/util/compat.py", line 211, in raise_
    raise exception
  File "/home/airflow/.local/lib/python3.12/site-packages/sqlalchemy/engine/base.py", line 3371, in _wrap_pool_connect
    return fn()
           ^^^^
  File "/home/airflow/.local/lib/python3.12/site-packages/sqlalchemy/pool/base.py", line 327, in connect
    return _ConnectionFairy._checkout(self)
           ^^^^^^^^^^^^^^^^^^^^^^^^^^^^^^^^
  File "/home/airflow/.local/lib/python3.12/site-packages/sqlalchemy/pool/base.py", line 894, in _checkout
    fairy = _ConnectionRecord.checkout(pool)
            ^^^^^^^^^^^^^^^^^^^^^^^^^^^^^^^^
  File "/home/airflow/.local/lib/python3.12/site-packages/sqlalchemy/pool/base.py", line 493, in checkout
    rec = pool._do_get()
          ^^^^^^^^^^^^^^
  File "/home/airflow/.local/lib/python3.12/site-packages/sqlalchemy/pool/impl.py", line 256, in _do_get
    return self._create_connection()
           ^^^^^^^^^^^^^^^^^^^^^^^^^
  File "/home/airflow/.local/lib/python3.12/site-packages/sqlalchemy/pool/base.py", line 273, in _create_connection
    return _ConnectionRecord(self)
           ^^^^^^^^^^^^^^^^^^^^^^^
  File "/home/airflow/.local/lib/python3.12/site-packages/sqlalchemy/pool/base.py", line 388, in __init__
    self.__connect()
  File "/home/airflow/.local/lib/python3.12/site-packages/sqlalchemy/pool/base.py", line 690, in __connect
    with util.safe_reraise():
         ^^^^^^^^^^^^^^^^^^^
  File "/home/airflow/.local/lib/python3.12/site-packages/sqlalchemy/util/langhelpers.py", line 70, in __exit__
    compat.raise_(
  File "/home/airflow/.local/lib/python3.12/site-packages/sqlalchemy/util/compat.py", line 211, in raise_
    raise exception
  File "/home/airflow/.local/lib/python3.12/site-packages/sqlalchemy/pool/base.py", line 686, in __connect
    self.dbapi_connection = connection = pool._invoke_creator(self)
                                         ^^^^^^^^^^^^^^^^^^^^^^^^^^
  File "/home/airflow/.local/lib/python3.12/site-packages/sqlalchemy/engine/create.py", line 574, in connect
    return dialect.connect(*cargs, **cparams)
           ^^^^^^^^^^^^^^^^^^^^^^^^^^^^^^^^^^
  File "/home/airflow/.local/lib/python3.12/site-packages/sqlalchemy/engine/default.py", line 598, in connect
    return self.dbapi.connect(*cargs, **cparams)
           ^^^^^^^^^^^^^^^^^^^^^^^^^^^^^^^^^^^^^
  File "/home/airflow/.local/lib/python3.12/site-packages/psycopg2/__init__.py", line 122, in connect
    conn = _connect(dsn, connection_factory=connection_factory, **kwasync)
           ^^^^^^^^^^^^^^^^^^^^^^^^^^^^^^^^^^^^^^^^^^^^^^^^^^^^^^^^^^^^^^^
sqlalchemy.exc.OperationalError: (psycopg2.OperationalError) could not translate host name "postgres" to address: Temporary failure in name resolution

(Background on this error at: https://sqlalche.me/e/14/e3q8)
[2024-11-21T06:03:46.114+0000] {job.py:254} ERROR - Job heartbeat failed with error. Scheduler is in unhealthy state
[2024-11-21T06:03:46.382+0000] {subprocess.py:110} INFO - Command exited with return code -9
[2024-11-21T06:03:48.477+0000] {taskinstance.py:3311} ERROR - Task failed with exception
Traceback (most recent call last):
  File "/home/airflow/.local/lib/python3.12/site-packages/airflow/models/taskinstance.py", line 767, in _execute_task
    result = _execute_callable(context=context, **execute_callable_kwargs)
             ^^^^^^^^^^^^^^^^^^^^^^^^^^^^^^^^^^^^^^^^^^^^^^^^^^^^^^^^^^^^^
  File "/home/airflow/.local/lib/python3.12/site-packages/airflow/models/taskinstance.py", line 733, in _execute_callable
    return ExecutionCallableRunner(
           ^^^^^^^^^^^^^^^^^^^^^^^^
  File "/home/airflow/.local/lib/python3.12/site-packages/airflow/utils/operator_helpers.py", line 252, in run
    return self.func(*args, **kwargs)
           ^^^^^^^^^^^^^^^^^^^^^^^^^^
  File "/home/airflow/.local/lib/python3.12/site-packages/airflow/models/baseoperator.py", line 417, in wrapper
    return func(self, *args, **kwargs)
           ^^^^^^^^^^^^^^^^^^^^^^^^^^^
  File "/home/airflow/.local/lib/python3.12/site-packages/airflow/operators/bash.py", line 276, in execute
    raise AirflowException(
airflow.exceptions.AirflowException: Bash command failed. The command returned a non-zero exit code -9.
[2024-11-21T06:03:48.717+0000] {logging_mixin.py:190} INFO - Task instance in failure state
[2024-11-21T06:03:48.719+0000] {logging_mixin.py:190} INFO - Task start:2024-11-21 06:03:09.854680+00:00 end:2024-11-21 06:03:48.601400+00:00 duration:38.74672
[2024-11-21T06:03:48.738+0000] {logging_mixin.py:190} INFO - Task:<Task(BashOperator): print> dag:<DAG: countries_pipeline> dagrun:<DagRun countries_pipeline @ 2024-11-21 06:02:41.915879+00:00: manual__2024-11-21T06:02:41.915879+00:00, state:running, queued_at: 2024-11-21 06:02:46.314376+00:00. externally triggered: True>
[2024-11-21T06:03:48.741+0000] {logging_mixin.py:190} INFO - Failure caused by Bash command failed. The command returned a non-zero exit code -9.
[2024-11-21T06:03:48.745+0000] {taskinstance.py:1225} INFO - Marking task as FAILED. dag_id=countries_pipeline, task_id=print, run_id=manual__2024-11-21T06:02:41.915879+00:00, execution_date=20241121T060241, start_date=20241121T060309, end_date=20241121T060348
[2024-11-21T06:03:49.235+0000] {taskinstance.py:340} INFO - ::group::Post task execution logs
[2024-11-21T06:03:49.296+0000] {standard_task_runner.py:124} ERROR - Failed to execute job 65 for task print (Bash command failed. The command returned a non-zero exit code -9.; 208)
Traceback (most recent call last):
  File "/home/airflow/.local/lib/python3.12/site-packages/airflow/task/task_runner/standard_task_runner.py", line 117, in _start_by_fork
    ret = args.func(args, dag=self.dag)
          ^^^^^^^^^^^^^^^^^^^^^^^^^^^^^
  File "/home/airflow/.local/lib/python3.12/site-packages/airflow/cli/cli_config.py", line 49, in command
    return func(*args, **kwargs)
           ^^^^^^^^^^^^^^^^^^^^^
  File "/home/airflow/.local/lib/python3.12/site-packages/airflow/utils/cli.py", line 116, in wrapper
    return f(*args, **kwargs)
           ^^^^^^^^^^^^^^^^^^
  File "/home/airflow/.local/lib/python3.12/site-packages/airflow/cli/commands/task_command.py", line 483, in task_run
    task_return_code = _run_task_by_selected_method(args, _dag, ti)
                       ^^^^^^^^^^^^^^^^^^^^^^^^^^^^^^^^^^^^^^^^^^^^
  File "/home/airflow/.local/lib/python3.12/site-packages/airflow/cli/commands/task_command.py", line 256, in _run_task_by_selected_method
    return _run_raw_task(args, ti)
           ^^^^^^^^^^^^^^^^^^^^^^^
  File "/home/airflow/.local/lib/python3.12/site-packages/airflow/cli/commands/task_command.py", line 341, in _run_raw_task
    return ti._run_raw_task(
           ^^^^^^^^^^^^^^^^^
  File "/home/airflow/.local/lib/python3.12/site-packages/airflow/utils/session.py", line 97, in wrapper
    return func(*args, session=session, **kwargs)
           ^^^^^^^^^^^^^^^^^^^^^^^^^^^^^^^^^^^^^^
  File "/home/airflow/.local/lib/python3.12/site-packages/airflow/models/taskinstance.py", line 3005, in _run_raw_task
    return _run_raw_task(
           ^^^^^^^^^^^^^^
  File "/home/airflow/.local/lib/python3.12/site-packages/airflow/models/taskinstance.py", line 273, in _run_raw_task
    TaskInstance._execute_task_with_callbacks(
  File "/home/airflow/.local/lib/python3.12/site-packages/airflow/models/taskinstance.py", line 3159, in _execute_task_with_callbacks
    result = self._execute_task(context, task_orig)
             ^^^^^^^^^^^^^^^^^^^^^^^^^^^^^^^^^^^^^^
  File "/home/airflow/.local/lib/python3.12/site-packages/airflow/models/taskinstance.py", line 3183, in _execute_task
    return _execute_task(self, context, task_orig)
           ^^^^^^^^^^^^^^^^^^^^^^^^^^^^^^^^^^^^^^^
  File "/home/airflow/.local/lib/python3.12/site-packages/airflow/models/taskinstance.py", line 767, in _execute_task
    result = _execute_callable(context=context, **execute_callable_kwargs)
             ^^^^^^^^^^^^^^^^^^^^^^^^^^^^^^^^^^^^^^^^^^^^^^^^^^^^^^^^^^^^^
  File "/home/airflow/.local/lib/python3.12/site-packages/airflow/models/taskinstance.py", line 733, in _execute_callable
    return ExecutionCallableRunner(
           ^^^^^^^^^^^^^^^^^^^^^^^^
  File "/home/airflow/.local/lib/python3.12/site-packages/airflow/utils/operator_helpers.py", line 252, in run
    return self.func(*args, **kwargs)
           ^^^^^^^^^^^^^^^^^^^^^^^^^^
  File "/home/airflow/.local/lib/python3.12/site-packages/airflow/models/baseoperator.py", line 417, in wrapper
    return func(self, *args, **kwargs)
           ^^^^^^^^^^^^^^^^^^^^^^^^^^^
  File "/home/airflow/.local/lib/python3.12/site-packages/airflow/operators/bash.py", line 276, in execute
    raise AirflowException(
airflow.exceptions.AirflowException: Bash command failed. The command returned a non-zero exit code -9.
[2024-11-21T06:03:49.494+0000] {local_task_job_runner.py:266} INFO - Task exited with return code 1
[2024-11-21T06:03:49.911+0000] {taskinstance.py:3895} INFO - 0 downstream tasks scheduled from follow-on schedule check
[2024-11-21T06:03:49.916+0000] {local_task_job_runner.py:245} INFO - ::endgroup::
